Workbook

Sheet 彙總
A1: 家教課程消費明細 — 彙總
A2: 資料來源：消費紀錄列印20260622_0037.pdf（駿斯運動 · 家教系統）
A3: 列印條件期間：2022-06-01 ~ 2026-06-22 產出日：2026-06-22
A4: 註：本檔 3,019 筆全部為「家教課程」消費；查無「會期/會員」購買品項。
A6: 交易概況
A7: 總交易筆數 | B7: =COUNT(家教課程明細!$A$2:$A$3020) -> 3019
A8: 實際金額合計 | B8: =SUM(家教課程明細!$O$2:$O$3020) -> 29786382
A9: 折扣(全)合計 | B9: =SUM(家教課程明細!$N$2:$N$3020) -> -2586258
A10: 紅利折扣合計 | B10: =SUM(家教課程明細!$M$2:$M$3020) -> 0
A11: 商品項數合計 | B11: =SUM(家教課程明細!$I$2:$I$3020) -> 4111
A12: 平均客單價 | B12: =ROUND(SUM(家教課程明細!$O$2:$O$3020)/COUNT(家教課程明細!$A$2:$A$3020),0) -> 9866
A14: 依扣款別統計
A15: 扣款別 | B15: 筆數 | C15: 實際金額 | D15: 金額占比
A16: 現金 | B16: =COUNTIF(家教課程明細!$L$2:$L$3020,"現金") -> 2684 | C16: =SUMIF(家教課程明細!$L$2:$L$3020,"現金",家教課程明細!$O$2:$O$3020) -> 26440909 | D16: =IF($C$16=0,0,$C$16/$C$20) -> 0.88768448
A17: 刷卡 | B17: =COUNTIF(家教課程明細!$L$2:$L$3020,"刷卡") -> 71 | C17: =SUMIF(家教課程明細!$L$2:$L$3020,"刷卡",家教課程明細!$O$2:$O$3020) -> 604710 | D17: =IF($C$17=0,0,$C$17/$C$20) -> 0.020301559
A18: 其他 | B18: =COUNTIF(家教課程明細!$L$2:$L$3020,"其他") -> 264 | C18: =SUMIF(家教課程明細!$L$2:$L$3020,"其他",家教課程明細!$O$2:$O$3020) -> 2740763 | D18: =IF($C$18=0,0,$C$18/$C$20) -> 0.092013961
A19: 儲值扣款 | B19: =COUNTIF(家教課程明細!$L$2:$L$3020,"儲值扣款") -> 0 | C19: =SUMIF(家教課程明細!$L$2:$L$3020,"儲值扣款",家教課程明細!$O$2:$O$3020) -> 0 | D19: =IF($C$19=0,0,$C$19/$C$20) -> 0
A20: 合計 | B20: =SUM($B$16:$B$19) -> 3019 | C20: =SUM($C$16:$C$19) -> 29786382 | D20: =IF($C$20=0,0,$C$20/$C$20) -> 1
A22: 依課程類別統計（依各交易第一項商品歸類）
A23: 課程類別 | B23: 筆數 | C23: 實際金額 | D23: 金額占比
A24: 1VS1 | B24: =COUNTIF(家教課程明細!$J$2:$J$3020,"1VS1") -> 1014 | C24: =SUMIF(家教課程明細!$J$2:$J$3020,"1VS1",家教課程明細!$O$2:$O$3020) -> 8571520 | D24: =IF($C$24=0,0,$C$24/$C$31) -> 0.2877664
A25: 1VS2 | B25: =COUNTIF(家教課程明細!$J$2:$J$3020,"1VS2") -> 1373 | C25: =SUMIF(家教課程明細!$J$2:$J$3020,"1VS2",家教課程明細!$O$2:$O$3020) -> 13353115 | D25: =IF($C$25=0,0,$C$25/$C$31) -> 0.44829597
A26: 1VS3 | B26: =COUNTIF(家教課程明細!$J$2:$J$3020,"1VS3") -> 397 | C26: =SUMIF(家教課程明細!$J$2:$J$3020,"1VS3",家教課程明細!$O$2:$O$3020) -> 4713562 | D26: =IF($C$26=0,0,$C$26/$C$31) -> 0.15824554
A27: 1VS4 | B27: =COUNTIF(家教課程明細!$J$2:$J$3020,"1VS4") -> 192 | C27: =SUMIF(家教課程明細!$J$2:$J$3020,"1VS4",家教課程明細!$O$2:$O$3020) -> 2549085 | D27: =IF($C$27=0,0,$C$27/$C$31) -> 0.085578873
A28: 1VS5 | B28: =COUNTIF(家教課程明細!$J$2:$J$3020,"1VS5") -> 39 | C28: =SUMIF(家教課程明細!$J$2:$J$3020,"1VS5",家教課程明細!$O$2:$O$3020) -> 525012 | D28: =IF($C$28=0,0,$C$28/$C$31) -> 0.017625907
A29: 1VS6 | B29: =COUNTIF(家教課程明細!$J$2:$J$3020,"1VS6") -> 4 | C29: =SUMIF(家教課程明細!$J$2:$J$3020,"1VS6",家教課程明細!$O$2:$O$3020) -> 74088 | D29: =IF($C$29=0,0,$C$29/$C$31) -> 0.0024873111
A30: 其他 | B30: =COUNTIF(家教課程明細!$J$2:$J$3020,"其他") -> 0 | C30: =SUMIF(家教課程明細!$J$2:$J$3020,"其他",家教課程明細!$O$2:$O$3020) -> 0 | D30: =IF($C$30=0,0,$C$30/$C$31) -> 0
A31: 合計 | B31: =SUM($B$24:$B$30) -> 3019 | C31: =SUM($C$24:$C$30) -> 29786382 | D31: =IF($C$31=0,0,$C$31/$C$31) -> 1

Sheet 家教課程明細
A1: 項次 | B1: 交易序號 | C1: 消費日期 | D1: 消費時間 | E1: 員工 | F1: 卡號 | G1: 會員姓名 | H1: 消費商品 | I1: 商品項數 | J1: 課程類別 | K1: 含試上 | L1: 扣款別 | M1: 紅利折扣 | N1: 折扣(全) | O1: 實際金額 | P1: 紅利 | Q1: 三民高中 | R1: 新北高中 | S1: 三重商工 | T1: 判斷是否有資料
A2: 1 | B2: 20260621122005010651 | C2: 46194 | D2: 12:20:05 | E2: 徐立珏 | F2: BQ115063 | G2: 徐漢潁、王允斌 | H2: 1. 家教1VS2 (20%) 1x9000 | I2: 1 | J2: 1VS2 | L2: 現金 | M2: 0 | N2: 0 | O2: 9000 | P2: 9000 | Q2: {=_xlfn.TEXTJOIN("、",TRUE,IF('學員資料-三民高中'!$B$2:$B$454=$F2,'學員資料-三民高中'!$G$2:$G$454,""))} | R2: {=_xlfn.TEXTJOIN("、",TRUE,IF('學員資料-新北高中'!$B$2:$B$583=$F2,'學員資料-新北高中'!$G$2:$G$583,""))} | S2: {=_xlfn.TEXTJOIN("、",TRUE,IF('學員資料-三重商工'!$B$2:$B$472=$F2,'學員資料-三重商工'!$G$2:$G$472,""))} -> 0986189878 | T2: =3-COUNTBLANK(Q2:S2) -> 1
A3: 2 | B3: 20260621121333010926 | C3: 46194 | D3: 12:13:33 | E3: 徐立珏 | F3: BQ115057 | G3: 張洛綾 | H3: 1. 家教1VS2 1x7500 | I3: 1 | J3: 1VS2 | L3: 現金 | M3: 0 | N3: 0 | O3: 7500 | P3: 7500 | Q3: {=_xlfn.TEXTJOIN("、",TRUE,IF('學員資料-三民高中'!$B$2:$B$454=$F3,'學員資料-三民高中'!$G$2:$G$454,""))} | R3: {=_xlfn.TEXTJOIN("、",TRUE,IF('學員資料-新北高中'!$B$2:$B$583=$F3,'學員資料-新北高中'!$G$2:$G$583,""))} | S3: {=_xlfn.TEXTJOIN("、",TRUE,IF('學員資料-三重商工'!$B$2:$B$472=$F3,'學員資料-三重商工'!$G$2:$G$472,""))} -> 0929933056 | T3: =3-COUNTBLANK(Q3:S3) -> 1
A4: 3 | B4: 20260620135011010760 | C4: 46193 | D4: 13:50:11 | E4: 葉瑋慈 | F4: BQ115062 | G4: 蔡育潔 阮偉銘 | H4: 1. 家教1VS2 (20%) 1x9000 | I4: 1 | J4: 1VS2 | L4: 其他 | M4: 0 | N4: 0 | O4: 9000 | P4: 9000 | Q4: {=_xlfn.TEXTJOIN("、",TRUE,IF('學員資料-三民高中'!$B$2:$B$454=$F4,'學員資料-三民高中'!$G$2:$G$454,""))} | R4: {=_xlfn.TEXTJOIN("、",TRUE,IF('學員資料-新北高中'!$B$2:$B$583=$F4,'學員資料-新北高中'!$G$2:$G$583,""))} -> 0911570278 | S4: {=_xlfn.TEXTJOIN("、",TRUE,IF('學員資料-三重商工'!$B$2:$B$472=$F4,'學員資料-三重商工'!$G$2:$G$472,""))} | T4: =3-COUNTBLANK(Q4:S4) -> 1
A5: 4 | B5: 20260620134733010911 | C5: 46193 | D5: 13:47:33 | E5: 葉瑋慈 | F5: BQ114132 | G5: 邱瑀昕 梁芷晴 | H5: 1. 家教1VS2 1x7500 | I5: 1 | J5: 1VS2 | L5: 其他 | M5: 0 | N5: 0 | O5: 7500 | P5: 7500 | Q5: {=_xlfn.TEXTJOIN("、",TRUE,IF('學員資料-三民高中'!$B$2:$B$454=$F5,'學員資料-三民高中'!$G$2:$G$454,""))} | R5: {=_xlfn.TEXTJOIN("、",TRUE,IF('學員資料-新北高中'!$B$2:$B$583=$F5,'學員資料-新北高中'!$G$2:$G$583,""))} | S5: {=_xlfn.TEXTJOIN("、",TRUE,IF('學員資料-三重商工'!$B$2:$B$472=$F5,'學員資料-三重商工'!$G$2:$G$472,""))} -> 0960714198 | T5: =3-COUNTBLANK(Q5:S5) -> 1
A6: 5 | B6: 20260620084333010403 | C6: 46193 | D6: 08:43:33 | E6: 葉瑋慈 | F6: AQ1141122 | G6: 吳凱恩 | H6: 1. 家教1VS1正 1x6900 | I6: 1 | J6: 1VS1 | L6: 現金 | M6: 0 | N6: 0 | O6: 6900 | P6: 6900 | Q6: {=_xlfn.TEXTJOIN("、",TRUE,IF('學員資料-三民高中'!$B$2:$B$454=$F6,'學員資料-三民高中'!$G$2:$G$454,""))} | R6: {=_xlfn.TEXTJOIN("、",TRUE,IF('學員資料-新北高中'!$B$2:$B$583=$F6,'學員資料-新北高中'!$G$2:$G$583,""))} -> 0932148373 | S6: {=_xlfn.TEXTJOIN("、",TRUE,IF('學員資料-三重商工'!$B$2:$B$472=$F6,'學員資料-三重商工'!$G$2:$G$472,""))} | T6: =3-COUNTBLANK(Q6:S6) -> 1
A7: 6 | B7: 20260620075155010011 | C7: 46193 | D7: 07:51:55 | E7: 葉瑋慈 | F7: BQ115061 | G7: 劉宇芯 | H7: 1. 家教1VS1正 1x6900 | I7: 1 | J7: 1VS1 | L7: 其他 | M7: 0 | N7: 0 | O7: 6900 | P7: 6900 | Q7: {=_xlfn.TEXTJOIN("、",TRUE,IF('學員資料-三民高中'!$B$2:$B$454=$F7,'學員資料-三民高中'!$G$2:$G$454,""))} | R7: {=_xlfn.TEXTJOIN("、",TRUE,IF('學員資料-新北高中'!$B$2:$B$583=$F7,'學員資料-新北高中'!$G$2:$G$583,""))} | S7: {=_xlfn.TEXTJOIN("、",TRUE,IF('學員資料-三重商工'!$B$2:$B$472=$F7,'學員資料-三重商工'!$G$2:$G$472,""))} | T7: =3-COUNTBLANK(Q7:S7) -> 0
A8: 7 | B8: 20260620074903010475 | C8: 46193 | D8: 07:49:03 | E8: 葉瑋慈 | F8: BQ115060 | G8: 廖有彬 | H8: 1. 家教1VS1正 1x6900 2. 家教1VS1正 1x6900 | I8: 2 | J8: 1VS1 | L8: 其他 | M8: 0 | N8: 0 | O8: 13800 | P8: 13800 | Q8: {=_xlfn.TEXTJOIN("、",TRUE,IF('學員資料-三民高中'!$B$2:$B$454=$F8,'學員資料-三民高中'!$G$2:$G$454,""))} | R8: {=_xlfn.TEXTJOIN("、",TRUE,IF('學員資料-新北高中'!$B$2:$B$583=$F8,'學員資料-新北高中'!$G$2:$G$583,""))} | S8: {=_xlfn.TEXTJOIN("、",TRUE,IF('學員資料-三重商工'!$B$2:$B$472=$F8,'學員資料-三重商工'!$G$2:$G$472,""))} | T8: =3-COUNTBLANK(Q8:S8) -> 0
A9: 8 | B9: 20260618202653010998 | C9: 46191 | D9: 20:26:53 | E9: 翁丞妤 | F9: CQ114236 | G9: 詹侑璁 | H9: 1. 家教1VS1正 1x6900 | I9: 1 | J9: 1VS1 | L9: 現金 | M9: 0 | N9: 0 | O9: 6900 | P9: 6900 | Q9: {=_xlfn.TEXTJOIN("、",TRUE,IF('學員資料-三民高中'!$B$2:$B$454=$F9,'學員資料-三民高中'!$G$2:$G$454,""))} -> 0926037987 | R9: {=_xlfn.TEXTJOIN("、",TRUE,IF('學員資料-新北高中'!$B$2:$B$583=$F9,'學員資料-新北高中'!$G$2:$G$583,""))} | S9: {=_xlfn.TEXTJOIN("、",TRUE,IF('學員資料-三重商工'!$B$2:$B$472=$F9,'學員資料-三重商工'!$G$2:$G$472,""))} | T9: =3-COUNTBLANK(Q9:S9) -> 1
A10: 9 | B10: 20260618201143010644 | C10: 46191 | D10: 20:11:43 | E10: 鄭琳魿 | F10: BQ115059 | G10: 陳詩⽻ | H10: 1. 家教1VS1正 1x6900 2. 家教1VS1正 1x6900 | I10: 2 | J10: 1VS1 | L10: 現金 | M10: 0 | N10: 0 | O10: 13800 | P10: 13800 | Q10: {=_xlfn.TEXTJOIN("、",TRUE,IF('學員資料-三民高中'!$B$2:$B$454=$F10,'學員資料-三民高中'!$G$2:$G$454,""))} | R10: {=_xlfn.TEXTJOIN("、",TRUE,IF('學員資料-新北高中'!$B$2:$B$583=$F10,'學員資料-新北高中'!$G$2:$G$583,""))} | S10: {=_xlfn.TEXTJOIN("、",TRUE,IF('學員資料-三重商工'!$B$2:$B$472=$F10,'學員資料-三重商工'!$G$2:$G$472,""))} -> 0976834520 | T10: =3-COUNTBLANK(Q10:S10) -> 1
A11: 10 | B11: 20260617205656010429 | C11: 46190 | D11: 20:56:56 | E11: 鄭琳魿 | F11: BQ115058 | G11: 李德揚 | H11: 1. 家教1VS1正 1x6900 | I11: 1 | J11: 1VS1 | L11: 現金 | M11: 0 | N11: 0 | O11: 6900 | P11: 6900 | Q11: {=_xlfn.TEXTJOIN("、",TRUE,IF('學員資料-三民高中'!$B$2:$B$454=$F11,'學員資料-三民高中'!$G$2:$G$454,""))} | R11: {=_xlfn.TEXTJOIN("、",TRUE,IF('學員資料-新北高中'!$B$2:$B$583=$F11,'學員資料-新北高中'!$G$2:$G$583,""))} | S11: {=_xlfn.TEXTJOIN("、",TRUE,IF('學員資料-三重商工'!$B$2:$B$472=$F11,'學員資料-三重商工'!$G$2:$G$472,""))} -> 0934020021 | T11: =3-COUNTBLANK(Q11:S11) -> 1
A12: 11 | B12: 20260616112531010621 | C12: 46189 | D12: 11:25:31 | E12: 莊尹玟 | F12: AQ1140616 | G12: 林晴川 | H12: 1. 家教1VS1正 1x6900 | I12: 1 | J12: 1VS1 | L12: 現金 | M12: 0 | N12: 0 | O12: 6900 | P12: 6900 | Q12: {=_xlfn.TEXTJOIN("、",TRUE,IF('學員資料-三民高中'!$B$2:$B$454=$F12,'學員資料-三民高中'!$G$2:$G$454,""))} | R12: {=_xlfn.TEXTJOIN("、",TRUE,IF('學員資料-新北高中'!$B$2:$B$583=$F12,'學員資料-新北高中'!$G$2:$G$583,""))} | S12: {=_xlfn.TEXTJOIN("、",TRUE,IF('學員資料-三重商工'!$B$2:$B$472=$F12,'學員資料-三重商工'!$G$2:$G$472,""))} | T12: =3-COUNTBLANK(Q12:S12) -> 0
A13: 12 | B13: 20260615184931010348 | C13: 46188 | D13: 18:49:31 | E13: 翁丞妤 | F13: CQ115148 | G13: 吳青諭 吳宇佑 | H13: 1. 家教1VS2 1x7500 2. 家教1VS2 1x7500 | I13: 2 | J13: 1VS2 | L13: 現金 | M13: 0 | N13: 0 | O13: 15000 | P13: 15000 | Q13: {=_xlfn.TEXTJOIN("、",TRUE,IF('學員資料-三民高中'!$B$2:$B$454=$F13,'學員資料-三民高中'!$G$2:$G$454,""))} -> 0931290858 | R13: {=_xlfn.TEXTJOIN("、",TRUE,IF('學員資料-新北高中'!$B$2:$B$583=$F13,'學員資料-新北高中'!$G$2:$G$583,""))} | S13: {=_xlfn.TEXTJOIN("、",TRUE,IF('學員資料-三重商工'!$B$2:$B$472=$F13,'學員資料-三重商工'!$G$2:$G$472,""))} | T13: =3-COUNTBLANK(Q13:S13) -> 1
... A16: 15 | B16: 20260615150506010371 | C16: 46188 | D16: 15:05:06 | E16: 鄭琳魿 | F16: BQ115040 | G16: 張景祥 | H16: 1. 家教1VS1 (20%) 1x8280 | I16: 1 | J16: 1VS1 | L16: 現金 | M16: 0 | N16: 0 | O16: 8280 | P16: 8280 | Q16: {=_xlfn.TEXTJOIN("、",TRUE,IF('學員資料-三民高中'!$B$2:$B$454=$F16,'學員資料-三民高中'!$G$2:$G$454,""))} | R16: {=_xlfn.TEXTJOIN("、",TRUE,IF('學員資料-新北高中'!$B$2:$B$583=$F16,'學員資料-新北高中'!$G$2:$G$583,""))} | S16: {=_xlfn.TEXTJOIN("、",TRUE,IF('學員資料-三重商工'!$B$2:$B$472=$F16,'學員資料-三重商工'!$G$2:$G$472,""))} -> 0958934004 | T16: =3-COUNTBLANK(Q16:S16) -> 1
A17: 16 | B17: 20260614163734010245 | C17: 46187 | D17: 16:37:34 | E17: 翁丞妤 | F17: BQ115057 | G17: 張洛綾 | H17: 1. 【試上】家教1VS2 1x1400 | I17: 1 | J17: 1VS2 | K17: 是 | L17: 現金 | M17: 0 | N17: 0 | O17: 1400 | P17: 1400 | Q17: {=_xlfn.TEXTJOIN("、",TRUE,IF('學員資料-三民高中'!$B$2:$B$454=$F17,'學員資料-三民高中'!$G$2:$G$454,""))} | R17: {=_xlfn.TEXTJOIN("、",TRUE,IF('學員資料-新北高中'!$B$2:$B$583=$F17,'學員資料-新北高中'!$G$2:$G$583,""))} | S17: {=_xlfn.TEXTJOIN("、",TRUE,IF('學員資料-三重商工'!$B$2:$B$472=$F17,'學員資料-三重商工'!$G$2:$G$472,""))} -> 0929933056 | T17: =3-COUNTBLANK(Q17:S17) -> 1
A18: 17 | B18: 20260614162139010577 | C18: 46187 | D18: 16:21:39 | E18: 翁丞妤 | F18: BQ115056 | G18: 林宜閒 林湘品 | H18: 1. 【試上】家教1VS2 (20%) 1x1680 | I18: 1 | J18: 1VS2 | K18: 是 | L18: 現金 | M18: 0 | N18: 0 | O18: 1680 | P18: 1680 | Q18: {=_xlfn.TEXTJOIN("、",TRUE,IF('學員資料-三民高中'!$B$2:$B$454=$F18,'學員資料-三民高中'!$G$2:$G$454,""))} | R18: {=_xlfn.TEXTJOIN("、",TRUE,IF('學員資料-新北高中'!$B$2:$B$583=$F18,'學員資料-新北高中'!$G$2:$G$583,""))} | S18: {=_xlfn.TEXTJOIN("、",TRUE,IF('學員資料-三重商工'!$B$2:$B$472=$F18,'學員資料-三重商工'!$G$2:$G$472,""))} -> 0965313230 | T18: =3-COUNTBLANK(Q18:S18) -> 1
A19: 18 | B19: 20260614161256010596 | C19: 46187 | D19: 16:12:56 | E19: 翁丞妤 | F19: BQ115053 | G19: 蔡東樺.蔡曜安.蔡曜⽻.蔡雨芯 | H19: 1. 家教1VS4 (20%) 1x14400 | I19: 1 | J19: 1VS4 | L19: 現金 | M19: 0 | N19: 0 | O19: 14400 | P19: 14400 | Q19: {=_xlfn.TEXTJOIN("、",TRUE,IF('學員資料-三民高中'!$B$2:$B$454=$F19,'學員資料-三民高中'!$G$2:$G$454,""))} | R19: {=_xlfn.TEXTJOIN("、",TRUE,IF('學員資料-新北高中'!$B$2:$B$583=$F19,'學員資料-新北高中'!$G$2:$G$583,""))} | S19: {=_xlfn.TEXTJOIN("、",TRUE,IF('學員資料-三重商工'!$B$2:$B$472=$F19,'學員資料-三重商工'!$G$2:$G$472,""))} -> 0926227506 | T19: =3-COUNTBLANK(Q19:S19) -> 1
A20: 19 | B20: 20260614141552010907 | C20: 46187 | D20: 14:15:52 | E20: 許雅雯 | F20: CQ114292 | G20: 賴彥誠.陳彩婕.詹佩螢 | H20: 1. 家教1VS3 1x9900 | I20: 1 | J20: 1VS3 | L20: 其他 | M20: 0 | N20: 0 | O20: 9900 | P20: 9900 | Q20: {=_xlfn.TEXTJOIN("、",TRUE,IF('學員資料-三民高中'!$B$2:$B$454=$F20,'學員資料-三民高中'!$G$2:$G$454,""))} -> 0989648031 | R20: {=_xlfn.TEXTJOIN("、",TRUE,IF('學員資料-新北高中'!$B$2:$B$583=$F20,'學員資料-新北高中'!$G$2:$G$583,""))} | S20: {=_xlfn.TEXTJOIN("、",TRUE,IF('學員資料-三重商工'!$B$2:$B$472=$F20,'學員資料-三重商工'!$G$2:$G$472,""))} | T20: =3-COUNTBLANK(Q20:S20) -> 1
A21: 20 | B21: 20260614132308010890 | C21: 46187 | D21: 13:23:08 | E21: 許雅雯 | F21: CQ115426 | G21: 季蔚帆.林宇桓 | H21: 1. 家教1VS2 1x7500 | I21: 1 | J21: 1VS2 | L21: 其他 | M21: 0 | N21: 0 | O21: 7500 | P21: 7500 | Q21: {=_xlfn.TEXTJOIN("、",TRUE,IF('學員資料-三民高中'!$B$2:$B$454=$F21,'學員資料-三民高中'!$G$2:$G$454,""))} -> 0918732834 | R21: {=_xlfn.TEXTJOIN("、",TRUE,IF('學員資料-新北高中'!$B$2:$B$583=$F21,'學員資料-新北高中'!$G$2:$G$583,""))} | S21: {=_xlfn.TEXTJOIN("、",TRUE,IF('學員資料-三重商工'!$B$2:$B$472=$F21,'學員資料-三重商工'!$G$2:$G$472,""))} | T21: =3-COUNTBLANK(Q21:S21) -> 1
A22: 21 | B22: 20260614131023010523 | C22: 46187 | D22: 13:10:23 | E22: 徐立珏 | F22: BQ113304 | G22: 楊沁瑜 | H22: 1. 家教1VS1 (20%) 1x8280 | I22: 1 | J22: 1VS1 | L22: 現金 | M22: 0 | N22: 0 | O22: 8280 | P22: 8280 | Q22: {=_xlfn.TEXTJOIN("、",TRUE,IF('學員資料-三民高中'!$B$2:$B$454=$F22,'學員資料-三民高中'!$G$2:$G$454,""))} | R22: {=_xlfn.TEXTJOIN("、",TRUE,IF('學員資料-新北高中'!$B$2:$B$583=$F22,'學員資料-新北高中'!$G$2:$G$583,""))} | S22: {=_xlfn.TEXTJOIN("、",TRUE,IF('學員資料-三重商工'!$B$2:$B$472=$F22,'學員資料-三重商工'!$G$2:$G$472,""))} -> 0910859275 | T22: =3-COUNTBLANK(Q22:S22) -> 1
A23: 22 | B23: 20260613172022010124 | C23: 46186 | D23: 17:20:22 | E23: 徐立珏 | F23: CQ114352 | G23: 賴欣葦 蘇宥宇 | H23: 1. 家教1VS2 1x7500 | I23: 1 | J23: 1VS2 | L23: 現金 | M23: 0 | N23: -750 | O23: 6750 | P23: 6750 | Q23: {=_xlfn.TEXTJOIN("、",TRUE,IF('學員資料-三民高中'!$B$2:$B$454=$F23,'學員資料-三民高中'!$G$2:$G$454,""))} -> 0937147856-1 | R23: {=_xlfn.TEXTJOIN("、",TRUE,IF('學員資料-新北高中'!$B$2:$B$583=$F23,'學員資料-新北高中'!$G$2:$G$583,""))} | S23: {=_xlfn.TEXTJOIN("、",TRUE,IF('學員資料-三重商工'!$B$2:$B$472=$F23,'學員資料-三重商工'!$G$2:$G$472,""))} | T23: =3-COUNTBLANK(Q23:S23) -> 1
A24: 23 | B24: 20260613162737010217 | C24: 46186 | D24: 16:27:37 | E24: 徐立珏 | F24: BQ115055 | G24: 黃禹嫣 黃翊恆 | H24: 1. 【試上】家教1VS2 1x1400 | I24: 1 | J24: 1VS2 | K24: 是 | L24: 現金 | M24: 0 | N24: 0 | O24: 1400 | P24: 1400 | Q24: {=_xlfn.TEXTJOIN("、",TRUE,IF('學員資料-三民高中'!$B$2:$B$454=$F24,'學員資料-三民高中'!$G$2:$G$454,""))} | R24: {=_xlfn.TEXTJOIN("、",TRUE,IF('學員資料-新北高中'!$B$2:$B$583=$F24,'學員資料-新北高中'!$G$2:$G$583,""))} | S24: {=_xlfn.TEXTJOIN("、",TRUE,IF('學員資料-三重商工'!$B$2:$B$472=$F24,'學員資料-三重商工'!$G$2:$G$472,""))} -> 0921845258 | T24: =3-COUNTBLANK(Q24:S24) -> 1
A25: 24 | B25: 20260613162711010977 | C25: 46186 | D25: 16:27:11 | E25: 葉瑋慈 | F25: AQ113272 | G25: 許翔宇 | H25: 1. 家教1VS1 (20%) 1x8280 | I25: 1 | J25: 1VS1 | L25: 其他 | M25: 0 | N25: -3312 | O25: 4968 | P25: 4968 | Q25: {=_xlfn.TEXTJOIN("、",TRUE,IF('學員資料-三民高中'!$B$2:$B$454=$F25,'學員資料-三民高中'!$G$2:$G$454,""))} | R25: {=_xlfn.TEXTJOIN("、",TRUE,IF('學員資料-新北高中'!$B$2:$B$583=$F25,'學員資料-新北高中'!$G$2:$G$583,""))} -> 0955977624 | S25: {=_xlfn.TEXTJOIN("、",TRUE,IF('學員資料-三重商工'!$B$2:$B$472=$F25,'學員資料-三重商工'!$G$2:$G$472,""))} | T25: =3-COUNTBLANK(Q25:S25) -> 1
A26: 25 | B26: 20260613162536010989 | C26: 46186 | D26: 16:25:36 | E26: 葉瑋慈 | F26: AQ115061 | G26: 許嘉⽂ | H26: 1. 家教1VS1 (20%) 1x8280 | I26: 1 | J26: 1VS1 | L26: 其他 | M26: 0 | N26: -3312 | O26: 4968 | P26: 4968 | Q26: {=_xlfn.TEXTJOIN("、",TRUE,IF('學員資料-三民高中'!$B$2:$B$454=$F26,'學員資料-三民高中'!$G$2:$G$454,""))} | R26: {=_xlfn.TEXTJOIN("、",TRUE,IF('學員資料-新北高中'!$B$2:$B$583=$F26,'學員資料-新北高中'!$G$2:$G$583,""))} | S26: {=_xlfn.TEXTJOIN("、",TRUE,IF('學員資料-三重商工'!$B$2:$B$472=$F26,'學員資料-三重商工'!$G$2:$G$472,""))} | T26: =3-COUNTBLANK(Q26:S26) -> 0
A27: 26 | B27: 20260613161510010705 | C27: 46186 | D27: 16:15:10 | E27: 葉瑋慈 | F27: AQ114125 | G27: 蘇重寧 蘇重燁 | H27: 1. 家教1VS2 (20%) 1x9000 | I27: 1 | J27: 1VS2 | L27: 其他 | M27: 0 | N27: 0 | O27: 9000 | P27: 9000 | Q27: {=_xlfn.TEXTJOIN("、",TRUE,IF('學員資料-三民高中'!$B$2:$B$454=$F27,'學員資料-三民高中'!$G$2:$G$454,""))} | R27: {=_xlfn.TEXTJOIN("、",TRUE,IF('學員資料-新北高中'!$B$2:$B$583=$F27,'學員資料-新北高中'!$G$2:$G$583,""))} -> 0911338706-1 | S27: {=_xlfn.TEXTJOIN("、",TRUE,IF('學員資料-三重商工'!$B$2:$B$472=$F27,'學員資料-三重商工'!$G$2:$G$472,""))} | T27: =3-COUNTBLANK(Q27:S27) -> 1
A28: 27 | B28: 20260613104612010034 | C28: 46186 | D28: 10:46:12 | E28: 莊柏彥 | F28: AQ11402001 | G28: 吳奕威.吳宜珊 | H28: 1. 家教1VS2 1x7500 2. 家教1VS2 1x7500 | I28: 2 | J28: 1VS2 | L28: 現金 | M28: 0 | N28: 0 | O28: 15000 | P28: 15000 | Q28: {=_xlfn.TEXTJOIN("、",TRUE,IF('學員資料-三民高中'!$B$2:$B$454=$F28,'學員資料-三民高中'!$G$2:$G$454,""))} | R28: {=_xlfn.TEXTJOIN("、",TRUE,IF('學員資料-新北高中'!$B$2:$B$583=$F28,'學員資料-新北高中'!$G$2:$G$583,""))} -> 0958631638 | S28: {=_xlfn.TEXTJOIN("、",TRUE,IF('學員資料-三重商工'!$B$2:$B$472=$F28,'學員資料-三重商工'!$G$2:$G$472,""))} | T28: =3-COUNTBLANK(Q28:S28) -> 1
A29: 28 | B29: 20260612183224010257 | C29: 46185 | D29: 18:32:24 | E29: 鄭琳魿 | F29: BQ111083 | G29: 元永翔.元永叡 | H29: 1. 家教1VS2 (20%) 1x9000 | I29: 1 | J29: 1VS2 | L29: 現金 | M29: 0 | N29: 0 | O29: 9000 | P29: 9000 | Q29: {=_xlfn.TEXTJOIN("、",TRUE,IF('學員資料-三民高中'!$B$2:$B$454=$F29,'學員資料-三民高中'!$G$2:$G$454,""))} | R29: {=_xlfn.TEXTJOIN("、",TRUE,IF('學員資料-新北高中'!$B$2:$B$583=$F29,'學員資料-新北高中'!$G$2:$G$583,""))} | S29: {=_xlfn.TEXTJOIN("、",TRUE,IF('學員資料-三重商工'!$B$2:$B$472=$F29,'學員資料-三重商工'!$G$2:$G$472,""))} -> 0913222254 | T29: =3-COUNTBLANK(Q29:S29) -> 1
A30: 29 | B30: 20260612171356010834 | C30: 46185 | D30: 17:13:56 | E30: 陳歆毓 | F30: CQ115145 | G30: 陳品匡 | H30: 1. 家教1VS1正 1x6900 | I30: 1 | J30: 1VS1 | L30: 現金 | M30: 0 | N30: 0 | O30: 6900 | P30: 6900 | Q30: {=_xlfn.TEXTJOIN("、",TRUE,IF('學員資料-三民高中'!$B$2:$B$454=$F30,'學員資料-三民高中'!$G$2:$G$454,""))} | R30: {=_xlfn.TEXTJOIN("、",TRUE,IF('學員資料-新北高中'!$B$2:$B$583=$F30,'學員資料-新北高中'!$G$2:$G$583,""))} | S30: {=_xlfn.TEXTJOIN("、",TRUE,IF('學員資料-三重商工'!$B$2:$B$472=$F30,'學員資料-三重商工'!$G$2:$G$472,""))} | T30: =3-COUNTBLANK(Q30:S30) -> 0
A31: 30 | B31: 20260612171104010882 | C31: 46185 | D31: 17:11:04 | E31: 陳歆毓 | F31: CQ114180 | G31: 房思妘 房暉軒何安格 | H31: 1. 家教1VS3 1x9900 | I31: 1 | J31: 1VS3 | L31: 現金 | M31: 0 | N31: 0 | O31: 9900 | P31: 9900 | Q31: {=_xlfn.TEXTJOIN("、",TRUE,IF('學員資料-三民高中'!$B$2:$B$454=$F31,'學員資料-三民高中'!$G$2:$G$454,""))} -> 0919360553 | R31: {=_xlfn.TEXTJOIN("、",TRUE,IF('學員資料-新北高中'!$B$2:$B$583=$F31,'學員資料-新北高中'!$G$2:$G$583,""))} | S31: {=_xlfn.TEXTJOIN("、",TRUE,IF('學員資料-三重商工'!$B$2:$B$472=$F31,'學員資料-三重商工'!$G$2:$G$472,""))} | T31: =3-COUNTBLANK(Q31:S31) -> 1
A32: 31 | B32: 20260612152302010153 | C32: 46185 | D32: 15:23:02 | E32: 徐立珏 | F32: AQ11407050 | G32: 陳瑀希 陳歆蕎 | H32: 1. 家教1VS2 1x7500 | I32: 1 | J32: 1VS2 | L32: 現金 | M32: 0 | N32: 0 | O32: 7500 | P32: 7500 | Q32: {=_xlfn.TEXTJOIN("、",TRUE,IF('學員資料-三民高中'!$B$2:$B$454=$F32,'學員資料-三民高中'!$G$2:$G$454,""))} | R32: {=_xlfn.TEXTJOIN("、",TRUE,IF('學員資料-新北高中'!$B$2:$B$583=$F32,'學員資料-新北高中'!$G$2:$G$583,""))} -> 0989026921 | S32: {=_xlfn.TEXTJOIN("、",TRUE,IF('學員資料-三重商工'!$B$2:$B$472=$F32,'學員資料-三重商工'!$G$2:$G$472,""))} | T32: =3-COUNTBLANK(Q32:S32) -> 1
A33: 32 | B33: 20260611163340010814 | C33: 46184 | D33: 16:33:40 | E33: 鄭琳魿 | F33: BQ115054 | G33: 蕭萁、蕭僑 | H33: 1. 家教1VS2 1x7500 | I33: 1 | J33: 1VS2 | L33: 現金 | M33: 0 | N33: 0 | O33: 7500 | P33: 7500 | Q33: {=_xlfn.TEXTJOIN("、",TRUE,IF('學員資料-三民高中'!$B$2:$B$454=$F33,'學員資料-三民高中'!$G$2:$G$454,""))} | R33: {=_xlfn.TEXTJOIN("、",TRUE,IF('學員資料-新北高中'!$B$2:$B$583=$F33,'學員資料-新北高中'!$G$2:$G$583,""))} | S33: {=_xlfn.TEXTJOIN("、",TRUE,IF('學員資料-三重商工'!$B$2:$B$472=$F33,'學員資料-三重商工'!$G$2:$G$472,""))} -> 0910554558 | T33: =3-COUNTBLANK(Q33:S33) -> 1
A34: 33 | B34: 20260611120635010727 | C34: 46184 | D34: 12:06:35 | E34: 莊尹玟 | F34: AQ1140611 | G34: 謝修有、謝修平 | H34: 1. 家教1VS2 1x7500 | I34: 1 | J34: 1VS2 | L34: 現金 | M34: 0 | N34: 0 | O34: 7500 | P34: 7500 | Q34: {=_xlfn.TEXTJOIN("、",TRUE,IF('學員資料-三民高中'!$B$2:$B$454=$F34,'學員資料-三民高中'!$G$2:$G$454,""))} | R34: {=_xlfn.TEXTJOIN("、",TRUE,IF('學員資料-新北高中'!$B$2:$B$583=$F34,'學員資料-新北高中'!$G$2:$G$583,""))} -> 0922852004 | S34: {=_xlfn.TEXTJOIN("、",TRUE,IF('學員資料-三重商工'!$B$2:$B$472=$F34,'學員資料-三重商工'!$G$2:$G$472,""))} | T34: =3-COUNTBLANK(Q34:S34) -> 1
A35: 34 | B35: 20260610185723010474 | C35: 46183 | D35: 18:57:23 | E35: 陳歆毓 | F35: BQ115032 | G35: 黃郁惠 | H35: 1. 家教1VS1 (20%) 1x8280 | I35: 1 | J35: 1VS1 | L35: 現金 | M35: 0 | N35: 0 | O35: 8280 | P35: 8280 | Q35: {=_xlfn.TEXTJOIN("、",TRUE,IF('學員資料-三民高中'!$B$2:$B$454=$F35,'學員資料-三民高中'!$G$2:$G$454,""))} | R35: {=_xlfn.TEXTJOIN("、",TRUE,IF('學員資料-新北高中'!$B$2:$B$583=$F35,'學員資料-新北高中'!$G$2:$G$583,""))} | S35: {=_xlfn.TEXTJOIN("、",TRUE,IF('學員資料-三重商工'!$B$2:$B$472=$F35,'學員資料-三重商工'!$G$2:$G$472,""))} -> 0919450143 | T35: =3-COUNTBLANK(Q35:S35) -> 1
A36: 35 | B36: 20260610172841010223 | C36: 46183 | D36: 17:28:41 | E36: 林佳琪 | F36: AQ113149 | G36: 蔡云箴 蔡紹泉 | H36: 1. 家教1VS2 1x7500 | I36: 1 | J36: 1VS2 | L36: 其他 | M36: 0 | N36: 0 | O36: 7500 | P36: 7500 | Q36: {=_xlfn.TEXTJOIN("、",TRUE,IF('學員資料-三民高中'!$B$2:$B$454=$F36,'學員資料-三民高中'!$G$2:$G$454,""))} | R36: {=_xlfn.TEXTJOIN("、",TRUE,IF('學員資料-新北高中'!$B$2:$B$583=$F36,'學員資料-新北高中'!$G$2:$G$583,""))} -> 0932386894 | S36: {=_xlfn.TEXTJOIN("、",TRUE,IF('學員資料-三重商工'!$B$2:$B$472=$F36,'學員資料-三重商工'!$G$2:$G$472,""))} | T36: =3-COUNTBLANK(Q36:S36) -> 1
... A60: 59 | B60: 20260601204707010867 | C60: 46174 | D60: 20:47:07 | E60: 鄭琳魿 | F60: BQ115049 | G60: 林帛宇.林⽻宸 | H60: 1. 家教1VS2 1x7500 | I60: 1 | J60: 1VS2 | L60: 現金 | M60: 0 | N60: -3000 | O60: 4500 | P60: 4500 | Q60: {=_xlfn.TEXTJOIN("、",TRUE,IF('學員資料-三民高中'!$B$2:$B$454=$F60,'學員資料-三民高中'!$G$2:$G$454,""))} | R60: {=_xlfn.TEXTJOIN("、",TRUE,IF('學員資料-新北高中'!$B$2:$B$583=$F60,'學員資料-新北高中'!$G$2:$G$583,""))} | S60: {=_xlfn.TEXTJOIN("、",TRUE,IF('學員資料-三重商工'!$B$2:$B$472=$F60,'學員資料-三重商工'!$G$2:$G$472,""))} -> 0933107597 | T60: =3-COUNTBLANK(Q60:S60) -> 1
A61: 60 | B61: 20260601204428010388 | C61: 46174 | D61: 20:44:28 | E61: 鄭琳魿 | F61: BQ115049 | G61: 林帛宇.林⽻宸 | H61: 1. 【試上】家教1VS2 1x1400 | I61: 1 | J61: 1VS2 | K61: 是 | L61: 現金 | M61: 0 | N61: -560 | O61: 840 | P61: 840 | Q61: {=_xlfn.TEXTJOIN("、",TRUE,IF('學員資料-三民高中'!$B$2:$B$454=$F61,'學員資料-三民高中'!$G$2:$G$454,""))} | R61: {=_xlfn.TEXTJOIN("、",TRUE,IF('學員資料-新北高中'!$B$2:$B$583=$F61,'學員資料-新北高中'!$G$2:$G$583,""))} | S61: {=_xlfn.TEXTJOIN("、",TRUE,IF('學員資料-三重商工'!$B$2:$B$472=$F61,'學員資料-三重商工'!$G$2:$G$472,""))} -> 0933107597 | T61: =3-COUNTBLANK(Q61:S61) -> 1
A62: 61 | B62: 20260601202941010989 | C62: 46174 | D62: 20:29:41 | E62: 翁丞妤 | F62: CQ113482 | G62: 鐘昊軒 鍾亦涵 | H62: 1. 家教1VS2 1x7500 | I62: 1 | J62: 1VS2 | L62: 現金 | M62: 0 | N62: 0 | O62: 7500 | P62: 7500 | Q62: {=_xlfn.TEXTJOIN("、",TRUE,IF('學員資料-三民高中'!$B$2:$B$454=$F62,'學員資料-三民高中'!$G$2:$G$454,""))} -> 0956558987 | R62: {=_xlfn.TEXTJOIN("、",TRUE,IF('學員資料-新北高中'!$B$2:$B$583=$F62,'學員資料-新北高中'!$G$2:$G$583,""))} | S62: {=_xlfn.TEXTJOIN("、",TRUE,IF('學員資料-三重商工'!$B$2:$B$472=$F62,'學員資料-三重商工'!$G$2:$G$472,""))} | T62: =3-COUNTBLANK(Q62:S62) -> 1
A63: 62 | B63: 20260601195402010312 | C63: 46174 | D63: 19:54:02 | E63: 翁丞妤 | F63: CQ115134 | G63: 廖翌昂 廖翌晴 | H63: 1. 家教1VS2 (20%) 1x9000 | I63: 1 | J63: 1VS2 | L63: 現金 | M63: 0 | N63: 0 | O63: 9000 | P63: 9000 | Q63: {=_xlfn.TEXTJOIN("、",TRUE,IF('學員資料-三民高中'!$B$2:$B$454=$F63,'學員資料-三民高中'!$G$2:$G$454,""))} | R63: {=_xlfn.TEXTJOIN("、",TRUE,IF('學員資料-新北高中'!$B$2:$B$583=$F63,'學員資料-新北高中'!$G$2:$G$583,""))} -> 0920191619-1 | S63: {=_xlfn.TEXTJOIN("、",TRUE,IF('學員資料-三重商工'!$B$2:$B$472=$F63,'學員資料-三重商工'!$G$2:$G$472,""))} | T63: =3-COUNTBLANK(Q63:S63) -> 1
A64: 63 | B64: 20260531194304010787 | C64: 46173 | D64: 19:43:04 | E64: 翁丞妤 | F64: AQ115531 | G64: 陳旼.余鎧婕.余宥安 | H64: 1. 家教1VS3 1x9900 | I64: 1 | J64: 1VS3 | L64: 現金 | M64: 0 | N64: 0 | O64: 9900 | P64: 9900 | Q64: {=_xlfn.TEXTJOIN("、",TRUE,IF('學員資料-三民高中'!$B$2:$B$454=$F64,'學員資料-三民高中'!$G$2:$G$454,""))} | R64: {=_xlfn.TEXTJOIN("、",TRUE,IF('學員資料-新北高中'!$B$2:$B$583=$F64,'學員資料-新北高中'!$G$2:$G$583,""))} -> 0919222678 | S64: {=_xlfn.TEXTJOIN("、",TRUE,IF('學員資料-三重商工'!$B$2:$B$472=$F64,'學員資料-三重商工'!$G$2:$G$472,""))} | T64: =3-COUNTBLANK(Q64:S64) -> 1
A65: 64 | B65: 20260531155707010005 | C65: 46173 | D65: 15:57:07 | E65: 葉瑋慈 | F65: BQ115048 | G65: 蘇珈語 蘇敬恩 | H65: 1. 【試上】家教1VS2 (20%) 1x1680 | I65: 1 | J65: 1VS2 | K65: 是 | L65: 現金 | M65: 0 | N65: 0 | O65: 1680 | P65: 1680 | Q65: {=_xlfn.TEXTJOIN("、",TRUE,IF('學員資料-三民高中'!$B$2:$B$454=$F65,'學員資料-三民高中'!$G$2:$G$454,""))} | R65: {=_xlfn.TEXTJOIN("、",TRUE,IF('學員資料-新北高中'!$B$2:$B$583=$F65,'學員資料-新北高中'!$G$2:$G$583,""))} | S65: {=_xlfn.TEXTJOIN("、",TRUE,IF('學員資料-三重商工'!$B$2:$B$472=$F65,'學員資料-三重商工'!$G$2:$G$472,""))} -> 0912915912 | T65: =3-COUNTBLANK(Q65:S65) -> 1
...

Sheet 工作表4
A1: 項次 | B1: 原卡號 | C1: 原姓名 | D1: 正規化卡號 | E1: 是否有資料 | F1: 比對方式 | G1: 會員編號(庫) | H1: 會員姓名(庫) | I1: 群組(庫) | J1: 館別 | K1: 行動電話 | L1: 市話
A2: 6 | B2: BQ115061 | C2: 劉宇芯 | D2: BQ115061 | E2: 有資料 | F2: 卡號相符 | G2: BQ115061 | H2: 劉宇芯 | I2: 新北館 | J2: 新北高中 | K2: 0928160963
A3: 7 | B3: BQ115060 | C3: 廖有彬 | D3: BQ115060 | E3: 有資料 | F3: 卡號相符 | G3: BQ115060 | H3: 廖有彬 | I3: 新北館 | J3: 新北高中 | K3: 0911563931
A4: 11 | B4: AQ1140616 | C4: 林晴川 | D4: AQ1140616 | E4: 有資料 | F4: 卡號相符 | G4: AQ1140616 | H4: 林晴川 | I4: 新北館 | J4: 新北高中 | K4: 0932012341
A5: 25 | B5: AQ115061 | C5: 許嘉⽂ | D5: AQ115061 | E5: 有資料 | F5: 卡號相符 | G5: AQ115061 | H5: 許嘉文 | I5: 新北館 | J5: 新北高中 | K5: 0932549778
A6: 29 | B6: CQ115145 | C6: 陳品匡 | D6: CQ115145 | E6: 有資料 | F6: 卡號相符 | G6: CQ115145 | H6: 陳品匡 | I6: 三民館 | J6: 三民高中 | K6: 0952641567 | L6: 0952641567
A7: 37 | B7: AQ1140610 | C7: 林星彤 | D7: AQ1140610 | E7: 有資料 | F7: 卡號相符 | G7: AQ1140610 | H7: 林星彤 | I7: 新北館 | J7: 新北高中 | K7: 0900394194
A8: 39 | B8: AQ11406091 | C8: 何沂玹、何晨瑞 | D8: AQ11406091 | E8: 有資料 | F8: 卡號相符 | G8: AQ11406091 | I8: 新北館 | J8: 新北高中 | K8: 0928084563
A9: 56 | B9: AQ1150604 | C9: 郭沐愛 | D9: AQ1150604 | E9: 有資料 | F9: 卡號相符 | G9: AQ1150604 | H9: 郭沐愛 | I9: 新北館 | J9: 新北高中 | K9: 0910192942
A10: 57 | B10: AQ1150605 | C10: 黎佳妮 | D10: AQ1150605 | E10: 有資料 | F10: 卡號相符 | G10: AQ1150605 | H10: 黎佳妮 | I10: 新北館 | J10: 新北高中 | K10: 0928880002
A11: 74 | B11: CQ115529 | C11: 王洛澄 鄭涵菲 | D11: CQ115529 | E11: 有資料 | F11: 卡號相符 | G11: CQ115529 | H11: 王洛澄 鄭涵菲 | I11: 新北館 | J11: 新北高中 | K11: 0916325053
A12: 77 | B12: AQ115060 | C12: 汪宥伶 | D12: AQ115060 | E12: 有資料 | F12: 卡號相符 | G12: AQ115060 | H12: 汪宥伶 | I12: 新北館 | J12: 新北高中 | K12: 0915694615
A13: 94 | C13: CQ113527-1姚奕鍇 | D13: CQ113527-1 | E13: 有資料 | F13: 卡號相符 | G13: CQ113527-1 | H13: 姚奕鍇 | I13: 三民課程 | J13: 三民高中 | K13: 0926181435
A14: 105 | B14: CQ115108 | C14: 蔡余婕 | D14: CQ115108 | E14: 有資料 | F14: 卡號相符 | G14: CQ115108 | H14: 蔡余婕 | I14: 三民館 | J14: 三民高中 | K14: 0976987109
A15: 130 | B15: CQ114010 | C15: 賴欣葦.蘇宥宇.蘇宥嘉 | D15: CQ114010 | E15: 有資料 | F15: 卡號相符 | G15: CQ114010 | H15: 賴欣葦.蘇宥宇.蘇宥嘉 | I15: 商工課程 | J15: 三重商工 | K15: 0937147856
A16: 150 | B16: CQ1150513 | C16: 陳奕華 | D16: CQ1150513 | E16: 有資料 | F16: 卡號相符 | G16: CQ1150513 | H16: 陳奕華 | I16: 三民館 | J16: 三民高中 | K16: 0982070815
A17: 160 | B17: AQ1140055 | C17: 葉宸鈞 | D17: AQ1140055 | E17: 有資料 | F17: 卡號相符 | G17: AQ1140055 | H17: 葉宸鈞 | I17: 新北館 | J17: 新北高中 | K17: 0911693649
A18: 162 | B18: CQ115103 | C18: 簡堃哲 | D18: CQ115103 | E18: 有資料 | F18: 卡號相符 | G18: CQ115103 | I18: 新北館 | J18: 新北高中 | K18: 0961330110 | L18: 0961330110
A19: 166 | B19: AQ115056 | C19: 宋允程，顏新纮 | D19: AQ115056 | E19: 有資料 | F19: 卡號相符 | G19: AQ115056 | I19: 新北館 | J19: 新北高中 | K19: 0919268429
A20: 205 | B20: AQ1141025 | C20: 張哲榮 | D20: AQ1141025 | E20: 有資料 | F20: 卡號相符 | G20: AQ1141025 | H20: 張哲榮 | I20: 新北館 | J20: 新北高中 | K20: 0921751876
A21: 215 | B21: CQ114010 | C21: 賴欣葦.蘇宥宇.蘇宥嘉 | D21: CQ114010 | E21: 有資料 | F21: 卡號相符 | G21: CQ114010 | H21: 賴欣葦.蘇宥宇.蘇宥嘉 | I21: 商工課程 | J21: 三重商工 | K21: 0937147856
A22: 268 | B22: BQ140006 | C22: 劉昕玥.林倢誼 | D22: BQ140006 | E22: 有資料 | F22: 卡號相符 | G22: BQ140006 | H22: 劉昕玥.林倢誼 | I22: 商工課程 | J22: 三重商工 | K22: 0922711546
A23: 426 | C23: CQ113527-1姚奕鍇 | D23: CQ113527-1 | E23: 有資料 | F23: 卡號相符 | G23: CQ113527-1 | H23: 姚奕鍇 | I23: 三民課程 | J23: 三民高中 | K23: 0926181435
A24: 430 | B24: BQ140007 | C24: 詹昕樺.詹沂穎 | D24: BQ140007 | E24: 有資料 | F24: 卡號相符 | G24: BQ140007 | H24: 詹昕樺.詹沂穎 | I24: 商工課程 | J24: 三重商工 | K24: 0935153303
A25: 495 | B25: AQ1141025 | C25: 張哲榮 | D25: AQ1141025 | E25: 有資料 | F25: 卡號相符 | G25: AQ1141025 | H25: 張哲榮 | I25: 新北館 | J25: 新北高中 | K25: 0921751876
A26: 543 | B26: AQ1141025 | C26: 張哲榮 | D26: AQ1141025 | E26: 有資料 | F26: 卡號相符 | G26: AQ1141025 | H26: 張哲榮 | I26: 新北館 | J26: 新北高中 | K26: 0921751876
A27: 575 | B27: AQ114002 | C27: 李采玹 | D27: AQ114002 | E27: 有資料 | F27: 卡號相符 | G27: AQ114002 | H27: 李采玹 | I27: 新北館 | J27: 新北高中 | K27: 0956454870
A28: 643 | B28: CQ114010 | C28: 賴欣葦.蘇宥宇.蘇宥嘉 | D28: CQ114010 | E28: 有資料 | F28: 卡號相符 | G28: CQ114010 | H28: 賴欣葦.蘇宥宇.蘇宥嘉 | I28: 商工課程 | J28: 三重商工 | K28: 0937147856
A29: 669 | B29: AQ1141025 | C29: 張哲榮 | D29: AQ1141025 | E29: 有資料 | F29: 卡號相符 | G29: AQ1141025 | H29: 張哲榮 | I29: 新北館 | J29: 新北高中 | K29: 0921751876
A30: 777 | B30: AQ113827 | C30: 李依倢 | D30: AQ113827 | E30: 有資料 | F30: 卡號相符 | G30: AQ113827 | H30: 李依倢 | I30: 新北館 | J30: 新北高中 | K30: 0936262633 | L30: 0936262633
A31: 848 | B31: cq1140601 | C31: 謝鈞宇 | D31: CQ1140601 | E31: 有資料 | F31: 卡號相符 | G31: cq1140601 | H31: 謝鈞宇 | I31: 三民館 | J31: 三民高中 | K31: 0913400123
A32: 861 | B32: BQ113156 | C32: 戴依辰 | D32: BQ113156 | E32: 有資料 | F32: 卡號相符 | G32: BQ113156 | H32: 戴依辰 | I32: 新北館 | J32: 新北高中 | K32: 0917601204 | L32: 0917601204
A33: 911 | C33: CQ113527-1姚奕鍇 | D33: CQ113527-1 | E33: 有資料 | F33: 卡號相符 | G33: CQ113527-1 | H33: 姚奕鍇 | I33: 三民課程 | J33: 三民高中 | K33: 0926181435
A34: 956 | B34: AQ113827 | C34: 李依倢 | D34: AQ113827 | E34: 有資料 | F34: 卡號相符 | G34: AQ113827 | H34: 李依倢 | I34: 新北館 | J34: 新北高中 | K34: 0936262633 | L34: 0936262633
A35: 1002 | C35: CQ11４２０１簡妍思 | D35: CQ114201 | E35: 有資料 | F35: 卡號相符 | G35: CQ11４２０１ | H35: 簡妍思 | I35: 三民課程 | J35: 三民高中 | K35: 0913245678 | L35: ０９６３００８３５１
A36: 1010 | B36: CQ114154 | C36: 陳云霈 | D36: CQ114154 | E36: 有資料 | F36: 卡號相符 | G36: CQ114154 | H36: 陳云霈 | I36: 新北館 | J36: 新北高中 | K36: 0920802321 | L36: 0920802321
A37: 1075 | B37: AQ113827 | C37: 李依倢 | D37: AQ113827 | E37: 有資料 | F37: 卡號相符 | G37: AQ113827 | H37: 李依倢 | I37: 新北館 | J37: 新北高中 | K37: 0936262633 | L37: 0936262633
A38: 1153 | B38: cq1140601 | C38: 謝鈞宇 | D38: CQ1140601 | E38: 有資料 | F38: 卡號相符 | G38: cq1140601 | H38: 謝鈞宇 | I38: 三民館 | J38: 三民高中 | K38: 0913400123
A39: 1159 | B39: CQ114154 | C39: 陳云霈 | D39: CQ114154 | E39: 有資料 | F39: 卡號相符 | G39: CQ114154 | H39: 陳云霈 | I39: 新北館 | J39: 新北高中 | K39: 0920802321 | L39: 0920802321
A40: 1163 | B40: CQ114010 | C40: 賴欣葦.蘇宥宇.蘇宥嘉 | D40: CQ114010 | E40: 有資料 | F40: 卡號相符 | G40: CQ114010 | H40: 賴欣葦.蘇宥宇.蘇宥嘉 | I40: 商工課程 | J40: 三重商工 | K40: 0937147856
...

Sheet 學員資料-三民高中
A1: 序號 | B1: 會員編號（舊） | C1: 姓名 | D1: 館別群組（原） | E1: 會員等級（原） | F1: 生日（民國） | G1: 行動電話 | H1: 電話 | I1: 卡片類別 | J1: 總消費 | K1: 來源檔案 | L1: 分類依據
A2: 1 | B2: AQ111426 | D2: 三民館 | E2: 三民家教會員 | G2: 0926187618-1 | I2: 儲值卡 | J2: 21120 | K2: 會員資料01.xls | L2: 家教等級
A3: 2 | B3: AQ113313 | C3: 王語涵、王語希 | D3: 三民課程 | E3: 三民家教會員 | G3: 0953112110 | I3: 儲值卡 | J3: 21900 | K3: 會員資料02.xls | L3: 課程群組、家教等級、多人姓名
A4: 3 | B4: AQ113567 | C4: 蕭致諺、卓柏言、卓柏樺、何宣諭 | D4: 三民課程 | E4: 三民家教會員 | G4: 0976521185 | I4: 儲值卡 | J4: 9504 | K4: 會員資料02.xls | L4: 課程群組、家教等級、多人姓名
A5: 4 | B5: AQ1140052 | C5: 徐子翔、徐溢成 | D5: 三民館 | E5: 三民家教會員 | G5: 0920016260-1 | I5: 儲值卡 | J5: 13500 | K5: 會員資料02.xls | L5: 家教等級、多人姓名
A6: 5 | B6: AQ114016 | C6: 林語晴、林品妍 | D6: 三民課程 | E6: 三民家教會員 | G6: 0955948981 | I6: 儲值卡 | J6: 7950 | K6: 會員資料02.xls | L6: 課程群組、家教等級、多人姓名
A7: 6 | B7: AQ1140706 | C7: 粘建凱、粘子紳 | D7: 三民館 | E7: 三民家教會員 | G7: 0988835148 | I7: 儲值卡 | J7: 15000 | K7: 會員資料02.xls | L7: 家教等級、多人姓名
A8: 7 | B8: AQ115036 | C8: 江玟誼、江姿誼 | D8: 三民館 | E8: 三民家教會員 | G8: 0926332176 | I8: 儲值卡 | J8: 18000 | K8: 會員資料02.xls | L8: 家教等級、多人姓名
A9: 8 | B9: C113132 | C9: 王志君 | D9: 三民課程 | E9: 一般會員 | G9: 0918236900 | I9: 儲值卡 | J9: 0 | K9: 會員資料04.xls | L9: 課程群組
A10: 9 | B10: C11457 | C10: 邱紹宸、邱兆翔、陳畇杉、陳畇佐 | D10: 三民課程 | E10: 三民家教會員 | G10: 0000000007 | I10: 儲值卡 | J10: 0 | K10: 會員資料04.xls | L10: 課程群組、家教等級、多人姓名
A11: 10 | B11: CQ109268 | C11: 連奕恩、張心瑞、張祐齊 | D11: 三民課程 | E11: 三民家教會員 | G11: CQ109268 | I11: 儲值卡 | J11: 9000 | K11: 會員資料04.xls | L11: 課程群組、家教等級、多人姓名
A12: 11 | B12: CQ109375 | C12: 王亮凱、江蘭馨 | D12: 三民課程 | E12: 三民家教會員 | G12: CQ112375 | I12: 儲值卡 | J12: 7200 | K12: 會員資料04.xls | L12: 課程群組、家教等級、多人姓名
A13: 12 | B13: CQ110002 | C13: 吳真幸 | D13: 三民課程 | E13: 三民家教會員 | G13: CQ110002 | I13: 儲值卡 | J13: 13200 | K13: 會員資料04.xls | L13: 課程群組、家教等級
A14: 13 | B14: CQ110284 | C14: 連奕恩 | D14: 三民課程 | E14: 三民家教會員 | G14: CQ110284 | I14: 儲值卡 | J14: 19800 | K14: 會員資料04.xls | L14: 課程群組、家教等級
... A50: 49 | B50: CQ113047 | C50: 李芯語、李芯媛 | D50: 三民課程 | E50: 三民家教會員 | G50: 0939113914 | I50: 儲值卡 | J50: 32922 | K50: 會員資料04.xls | L50: 課程群組、家教等級、多人姓名
A51: 50 | B51: CQ113049 | D51: 三民館 | E51: 三民家教會員 | G51: 0926685502 | I51: 儲值卡 | J51: 31680 | K51: 會員資料04.xls | L51: 家教等級
A52: 51 | B52: CQ1130504 | C52: 余沐樺、余博洋 | D52: 三民課程 | E52: 三民家教會員 | G52: 0916175109 | I52: 儲值卡 | J52: 14700 | K52: 會員資料04.xls | L52: 課程群組、家教等級、多人姓名
A53: 52 | B53: CQ1130505 | C53: 謝念佑、謝承佑 | D53: 三民課程 | E53: 三民家教會員 | G53: 0983499307 | I53: 儲值卡 | J53: 12672 | K53: 會員資料04.xls | L53: 課程群組、家教等級、多人姓名
A54: 53 | B54: CQ1130524 | C54: 吳雨霏、李聿晴、李聿翔 | D54: 三民課程 | E54: 三民家教會員 | G54: 0975202780 | I54: 儲值卡 | J54: 9000 | K54: 會員資料04.xls | L54: 課程群組、家教等級、多人姓名
A55: 54 | B55: CQ1130529 | C55: 楊又璇 | D55: 三民課程 | E55: 三民家教會員 | G55: 09123456774 | I55: 儲值卡 | J55: 1200 | K55: 會員資料04.xls | L55: 課程群組、家教等級
A56: 55 | B56: CQ113064 | C56: 潘宣妤、顏子琪、駱又寧、李允心 | D56: 三民課程 | E56: 三民家教會員 | G56: 0926061999-1 | I56: 儲值卡 | J56: 10800 | K56: 會員資料04.xls | L56: 課程群組、家教等級、多人姓名
A57: 56 | B57: CQ113097 | C57: 何芸菲、黃云希、蔡濬陽 | D57: 三民課程 | E57: 三民家教會員 | G57: 0972526397 | I57: 儲值卡 | J57: 7920 | K57: 會員資料04.xls | L57: 課程群組、家教等級、多人姓名
A58: 57 | B58: CQ1131000 | C58: 陳煜凱、李宜頡、李芮綺、李梓蕾 | D58: 三民館 | E58: 三民家教會員 | G58: 0933888191 | H58: 0933888191 | I58: 儲值卡 | J58: 19008 | K58: 會員資料04.xls | L58: 家教等級、多人姓名
A59: 58 | B59: CQ1131001 | C59: 廖冠瑀 | D59: 三民課程 | E59: 三民家教會員 | G59: 0933526945 | I59: 儲值卡 | J59: 11880 | K59: 會員資料04.xls | L59: 課程群組、家教等級
A60: 59 | B60: CQ1131002 | C60: 鄭羽辰 | D60: 三民課程 | E60: 三民家教會員 | G60: 0939623233 | I60: 儲值卡 | J60: 38145 | K60: 會員資料04.xls | L60: 課程群組、家教等級
A61: 60 | B61: CQ1131003 | C61: 卓孟鋮、卓鈺珵 | D61: 三民課程 | E61: 三民家教會員 | G61: 0911956440 | I61: 儲值卡 | J61: 12960 | K61: 會員資料04.xls | L61: 課程群組、家教等級、多人姓名
A62: 61 | B62: CQ1131004 | C62: 杜毅飛、李帛暘 | D62: 三民館 | E62: 三民家教會員 | G62: 0921641535 | H62: 0921641535 | I62: 儲值卡 | J62: 6480 | K62: 會員資料04.xls | L62: 家教等級、多人姓名
A63: 62 | B63: CQ1131005 | C63: 李瑀娜 | D63: 三民課程 | E63: 三民家教會員 | G63: 0933765644 | I63: 儲值卡 | J63: 11880 | K63: 會員資料04.xls | L63: 課程群組、家教等級
A64: 63 | B64: CQ1131007 | C64: 黃柏睿、陳映充 | D64: 三民課程 | E64: 三民家教會員 | G64: 0913597806 | H64: 0913597806 | I64: 儲值卡 | J64: 41685 | K64: 會員資料04.xls | L64: 課程群組、家教等級、多人姓名
A65: 64 | B65: CQ1131008 | C65: 蔡政穎 | D65: 三民課程 | E65: 三民家教會員 | G65: 0921501116 | H65: 0921501116 | I65: 儲值卡 | J65: 5940 | K65: 會員資料04.xls | L65: 課程群組、家教等級
A66: 65 | B66: CQ1131009 | C66: 鄭丞晏、鄭語�� | D66: 三民課程 | E66: 三民家教會員 | G66: 0917657387 | H66: 0917657387 | I66: 儲值卡 | J66: 6480 | K66: 會員資料04.xls | L66: 課程群組、家教等級、多人姓名
A67: 66 | B67: CQ113101 | C67: 廖禹晴、廖禹潼 | D67: 三民館 | E67: 三民家教會員 | G67: 0952128229 | I67: 儲值卡 | J67: 7500 | K67: 會員資料04.xls | L67: 家教等級、多人姓名
A68: 67 | B68: CQ1131010 | C68: 周羽莘、周語澄、黃郁琁 | D68: 三民課程 | E68: 三重家教會員 | G68: 0935827666 | H68: 0935827666 | I68: 儲值卡 | J68: 49500 | K68: 會員資料04.xls | L68: 課程群組、家教等級、多人姓名
A69: 68 | B69: CQ1131011 | C69: 謝昇晉、黃芊瑋、廖俞晴、廖子晴 | D69: 三民課程 | E69: 三民家教會員 | G69: 0961258777 | I69: 儲值卡 | J69: 19008 | K69: 會員資料04.xls | L69: 課程群組、家教等級、多人姓名
A70: 69 | B70: CQ1131012 | C70: 劉炳鋒、劉芷妤、劉承恩 | D70: 三民課程 | E70: 三民家教會員 | G70: 0980340349 | H70: 0980340349 | I70: 儲值卡 | J70: 15840 | K70: 會員資料04.xls | L70: 課程群組、家教等級、多人姓名
A71: 70 | B71: CQ1131019 | C71: 陳冠瑋 | D71: 三民課程 | E71: 三民家教會員 | G71: 0955109120 | I71: 儲值卡 | J71: 18435 | K71: 會員資料04.xls | L71: 課程群組、家教等級
A72: 71 | B72: CQ113108 | C72: 王琳雅、王筱筑 | D72: 三民課程 | E72: 三民家教會員 | G72: 0939235050 | I72: 儲值卡 | J72: 6480 | K72: 會員資料04.xls | L72: 課程群組、家教等級、多人姓名
A73: 72 | B73: CQ113109 | C73: 林梓垚、黃宇程 | D73: 三民館 | E73: 一般會員 | G73: 0932235653 | H73: 0932235653 | I73: 儲值卡 | J73: 7500 | K73: 會員資料04.xls | L73: 多人姓名
A74: 73 | B74: CQ1131095 | C74: 郭語恩、連予曦、李以樂 | D74: 三民館 | E74: 三民家教會員 | G74: 0939684088 | H74: 0939684088 | I74: 儲值卡 | J74: 14400 | K74: 會員資料04.xls | L74: 家教等級、多人姓名
A75: 74 | B75: CQ1131096 | C75: 陳睿安、施芸潔、陳芸希 | D75: 三民課程 | E75: 三民家教會員 | G75: 0916710620-1 | I75: 儲值卡 | J75: 23760 | K75: 會員資料04.xls | L75: 課程群組、家教等級、多人姓名
...

Sheet 學員資料-三重商工
A1: 序號 | B1: 會員編號（舊） | C1: 姓名 | D1: 館別群組（原） | E1: 會員等級（原） | F1: 生日（民國） | G1: 行動電話 | H1: 電話 | I1: 卡片類別 | J1: 總消費 | K1: 來源檔案 | L1: 分類依據
A2: 1 | B2: BQ113330 | C2: 陳宜蓁陳聖樺 | D2: 三重館 | E2: 三重家教會員 | G2: 0921812796 | I2: 儲值卡 | J2: 38952 | K2: 會員資料01.xls | L2: 家教等級、多人姓名
A3: 2 | B3: AQ111104 | C3: 許子彤、許葳 | D3: 商工課程 | E3: 三重家教會員 | G3: 0958729541 | I3: 儲值卡 | J3: 6120 | K3: 會員資料01.xls | L3: 課程群組、家教等級、多人姓名
A4: 3 | B4: AQ112496 | C4: 陳妍安、陳妍均 | D4: 商工課程 | E4: 三重家教會員 | G4: 0916242232 | I4: 儲值卡 | J4: 49440 | K4: 會員資料01.xls | L4: 課程群組、家教等級、多人姓名
A5: 4 | B5: AQ113950 | C5: 陳柏辰、陳虹伶、蘇彥丞、吳孟軒 | D5: 三重館 | E5: 新北家教會員 | G5: 0916982997 | I5: 儲值卡 | J5: 10800 | K5: 會員資料02.xls | L5: 家教等級、多人姓名
A6: 5 | B6: AQ114057 | D6: 商工課程 | E6: 一般會員 | G6: 0913009897 | I6: 儲值卡 | J6: 9900 | K6: 會員資料02.xls | L6: 課程群組
A7: 6 | B7: AQ1140628 | C7: 謝東哲、謝依靜、謝佩璇 | D7: 商工課程 | E7: 三重家教會員 | G7: 0952663043 | I7: 儲值卡 | J7: 9900 | K7: 會員資料02.xls | L7: 課程群組、家教等級、多人姓名
A8: 7 | B8: B13103 | C8: 楊政修 | D8: 三重館 | E8: 三重家教會員 | G8: 0911553712 | I8: 儲值卡 | J8: 0 | K8: 會員資料02.xls | L8: 家教等級
A9: 8 | B9: B13104 | C9: 劉憶瑩 | D9: 三重館 | E9: 三重家教會員 | G9: 0919329712 | I9: 儲值卡 | J9: 0 | K9: 會員資料02.xls | L9: 家教等級
A10: 9 | B10: BQ108455 | C10: 曾子豪、曾子瑜 | D10: 商工課程 | E10: 三重家教會員 | G10: 0933074090 | I10: 儲值卡 | J10: 17280 | K10: 會員資料02.xls | L10: 課程群組、家教等級、多人姓名
A11: 10 | B11: BQ109062 | C11: 陳睫晞、胡賀鈞、陳睫禹、胡庭瑄 | D11: 商工課程 | E11: 三重家教會員 | G11: AQ0017 | I11: 儲值卡 | J11: 24430 | K11: 會員資料03.xls | L11: 課程群組、家教等級、多人姓名
A12: 11 | B12: BQ109089 | C12: 陳慧屏、蔡侑庭、蔡承翰 | D12: 商工課程 | E12: 三重家教會員 | G12: AQ0019 | I12: 儲值卡 | J12: 6885 | K12: 會員資料03.xls | L12: 課程群組、家教等級、多人姓名
A13: 12 | B13: BQ109198 | C13: 張鼎綸、張妍妍 | D13: 商工課程 | E13: 三重家教會員 | G13: 0952657693 | I13: 儲值卡 | J13: 7200 | K13: 會員資料03.xls | L13: 課程群組、家教等級、多人姓名
A14: 13 | B14: BQ109354 | C14: 李宜軒、李沅軒 | D14: 商工課程 | E14: 三重家教會員 | G14: AQ0020 | I14: 儲值卡 | J14: 6480 | K14: 會員資料03.xls | L14: 課程群組、家教等級、多人姓名
A15: 14 | B15: BQ109533 | C15: 黃諾恩、李睿玹、張有紳 | D15: 商工課程 | E15: 三重家教會員 | G15: 0958934013 | I15: 儲值卡 | J15: 9000 | K15: 會員資料03.xls | L15: 課程群組、家教等級、多人姓名
A16: 15 | B16: BQ110027 | C16: 謝旭翔、謝承叡 | D16: 商工課程 | E16: 三重家教會員 | G16: 0929169103 | I16: 儲值卡 | J16: 8640 | K16: 會員資料03.xls | L16: 課程群組、家教等級、多人姓名
A17: 16 | B17: BQ110080 | C17: 劉竫宥、李渟嶼、亦霖、思羽 | D17: 商工課程 | E17: 三重家教會員 | G17: AQ0006 | I17: 儲值卡 | J17: 10800 | K17: 會員資料03.xls | L17: 課程群組、家教等級、多人姓名
A18: 17 | B18: BQ111033 | C18: 賴韻晴、賴冠銓 | D18: 商工課程 | E18: 三重家教會員 | G18: DE61540306 | I18: 儲值卡 | J18: 0 | K18: 會員資料03.xls | L18: 課程群組、家教等級、多人姓名
... A35: 34 | B35: BQ112128 | C35: 林東德 | D35: 商工課程 | E35: 三重家教會員 | G35: 0900111222 | I35: 儲值卡 | J35: 6000 | K35: 會員資料03.xls | L35: 課程群組、家教等級
A36: 35 | B36: BQ112132 | C36: 謝昕辰謝昀琪 | D36: 三重館 | E36: 三重家教會員 | G36: 0953289313 | H36: 0953289313 | I36: 儲值卡 | J36: 29700 | K36: 會員資料03.xls | L36: 家教等級、多人姓名
A37: 36 | B37: BQ112155 | C37: 鄭宇廷、林煦昊、林于蕎 | D37: 商工課程 | E37: 三重家教會員 | G37: 0983916765-2 | I37: 儲值卡 | J37: 9720 | K37: 會員資料03.xls | L37: 課程群組、家教等級、多人姓名
A38: 37 | B38: BQ112159 | C38: 李秉誠 | D38: 三重館 | E38: 三重家教會員 | G38: 0976613417 | I38: 儲值卡 | J38: 25740 | K38: 會員資料03.xls | L38: 家教等級
A39: 38 | B39: BQ112196 | C39: 黃郁珺 | D39: 商工課程 | E39: 三重家教會員 | G39: 0968775079 | I39: 儲值卡 | J39: 7200 | K39: 會員資料03.xls | L39: 課程群組、家教等級
A40: 39 | B40: BQ112220 | C40: 賴立軒 | D40: 商工課程 | E40: 三重家教會員 | G40: 0920107013 | I40: 儲值卡 | J40: 6600 | K40: 會員資料03.xls | L40: 課程群組、家教等級
A41: 40 | B41: BQ112235 | C41: 陳品邑 | D41: 商工課程 | E41: 三重家教會員 | G41: 0955742659 | I41: 儲值卡 | J41: 7200 | K41: 會員資料03.xls | L41: 課程群組、家教等級
A42: 41 | B42: BQ112236 | C42: 陳瑜采 | D42: 商工課程 | E42: 三重家教會員 | G42: 0989800234 | I42: 儲值卡 | J42: 7200 | K42: 會員資料03.xls | L42: 課程群組、家教等級
A43: 42 | B43: BQ112265 | D43: 商工課程 | E43: 三重家教會員 | G43: 0937039857 | I43: 儲值卡 | J43: 6600 | K43: 會員資料03.xls | L43: 課程群組、家教等級
A44: 43 | B44: BQ112290 | C44: 陳耑佑 | D44: 三重館 | E44: 三重家教會員 | G44: 0978666555 | I44: 儲值卡 | J44: 0 | K44: 會員資料03.xls | L44: 家教等級
A45: 44 | B45: BQ112298 | D45: 商工課程 | E45: 三重家教會員 | G45: 0919730925 | I45: 儲值卡 | J45: 9720 | K45: 會員資料03.xls | L45: 課程群組、家教等級
A46: 45 | B46: BQ112310 | C46: 楊捷翔、楊曜安 | D46: 商工課程 | E46: 三重家教會員 | G46: 0924029887 | I46: 儲值卡 | J46: 8640 | K46: 會員資料03.xls | L46: 課程群組、家教等級、多人姓名
A47: 46 | B47: BQ112317 | C47: 劉宥彤、劉又甄、沈柏宇、沈奕丞 | D47: 商工課程 | E47: 三重家教會員 | G47: 0937752031 | I47: 儲值卡 | J47: 20736 | K47: 會員資料03.xls | L47: 課程群組、家教等級、多人姓名
A48: 47 | B48: BQ112337 | C48: 蔡薰賢、洪楨雅 | D48: 商工課程 | E48: 三重家教會員 | G48: 0910951005 | I48: 儲值卡 | J48: 6480 | K48: 會員資料03.xls | L48: 課程群組、家教等級、多人姓名
A49: 48 | B49: BQ112338 | C49: 詹紹柔、詹樂昀、詹顥宸 | D49: 商工課程 | E49: 三重家教會員 | G49: 0963469636 | I49: 儲值卡 | J49: 32400 | K49: 會員資料03.xls | L49: 課程群組、家教等級、多人姓名
A50: 49 | B50: BQ112349 | C50: 涂宬睿 | D50: 商工課程 | E50: 三重家教會員 | G50: 0939693212 | I50: 儲值卡 | J50: 19440 | K50: 會員資料03.xls | L50: 課程群組、家教等級
A51: 50 | B51: BQ112355 | C51: 張博睿、張凱睿 | D51: 商工課程 | E51: 三重家教會員 | G51: 0987003036 | I51: 儲值卡 | J51: 8640 | K51: 會員資料03.xls | L51: 課程群組、家教等級、多人姓名
A52: 51 | B52: BQ112356 | C52: 曾秀茹、江佳霖、施儀欣、黃雋恩 | D52: 商工課程 | E52: 三重家教會員 | G52: 0912263473 | I52: 儲值卡 | J52: 11520 | K52: 會員資料03.xls | L52: 課程群組、家教等級、多人姓名
A53: 52 | B53: BQ112359 | C53: 柏廷 | D53: 商工課程 | E53: 三重家教會員 | G53: 0955810185 | I53: 儲值卡 | J53: 12960 | K53: 會員資料03.xls | L53: 課程群組、家教等級
A54: 53 | B54: BQ112369 | C54: 張佳禾、張承宗 | D54: 商工課程 | E54: 三重家教會員 | G54: 0980594643 | I54: 儲值卡 | J54: 15552 | K54: 會員資料03.xls | L54: 課程群組、家教等級、多人姓名
A55: 54 | B55: BQ112385 | C55: 林秀英 | D55: 商工課程 | E55: 三重家教會員 | G55: 0935973139 | I55: 儲值卡 | J55: 6600 | K55: 會員資料03.xls | L55: 課程群組、家教等級
A56: 55 | B56: BQ112401 | C56: 劉邏 | D56: 商工課程 | E56: 三重家教會員 | G56: 0958112332 | I56: 儲值卡 | J56: 6600 | K56: 會員資料03.xls | L56: 課程群組、家教等級
...

Sheet 學員資料-新北高中
A1: 序號 | B1: 會員編號（舊） | C1: 姓名 | D1: 館別群組（原） | E1: 會員等級（原） | F1: 生日（民國） | G1: 行動電話 | H1: 電話 | I1: 卡片類別 | J1: 總消費 | K1: 來源檔案 | L1: 分類依據
A2: 1 | B2: 1150202 | C2: 蔡昕桐、蔡昕恩 | D2: 新北課程 | E2: 新北家教會員 | G2: 0958088666 | I2: 儲值卡 | J2: 25920 | K2: 會員資料01.xls | L2: 課程群組、家教等級、多人姓名
A3: 2 | B3: 1150203 | C3: 陳柏碩、陳霖 | D3: 新北館 | E3: 一般會員 | G3: 0960926856 | I3: 儲值卡 | J3: 8640 | K3: 會員資料01.xls | L3: 多人姓名
A4: 3 | B4: A1131001 | C4: 李秉祐、李家丞、馬靖峰 | D4: 新北館 | E4: 一般會員 | G4: 0932728089 | I4: 儲值卡 | J4: 15840 | K4: 會員資料01.xls | L4: 多人姓名
A5: 4 | B5: A113308 | C5: 李東泰、李雅安、李珮安 | D5: 新北館 | E5: 一般會員 | G5: 0986119202 | I5: 儲值卡 | J5: 9000 | K5: 會員資料01.xls | L5: 多人姓名
A6: 5 | B6: A11402 | C6: 林柏辰 | D6: 新北館 | E6: 新北家教會員 | G6: 0987277897 | I6: 儲值卡 | J6: 0 | K6: 會員資料01.xls | L6: 家教等級
A7: 6 | B7: A130803063 | C7: 許錚 | D7: 新北館 | E7: 新北家教會員 | G7: 0932345516 | H7: 0932345516 | I7: 儲值卡 | J7: 0 | K7: 會員資料01.xls | L7: 家教等級
A8: 7 | B8: A130926985 | C8: 鄭斌鴻、侯文娟 | D8: 新北課程 | E8: 新北家教會員 | G8: 0952260875 | I8: 儲值卡 | J8: 22800 | K8: 會員資料01.xls | L8: 課程群組、家教等級、多人姓名
A9: 8 | B9: AQ0007 | C9: 顧子琪、顧子賢、潘威佑、潘宣妤 | D9: 新北課程 | E9: 新北家教會員 | G9: AQ0007 | I9: 儲值卡 | J9: 12672 | K9: 會員資料01.xls | L9: 課程群組、家教等級、多人姓名
A10: 9 | B10: AQ01140723 | C10: 陳禹甯、翁楷玹、翁楷淳、陳禹樸 | D10: 新北館 | E10: 新北家教會員 | G10: 0987168289 | I10: 儲值卡 | J10: 0 | K10: 會員資料01.xls | L10: 家教等級、多人姓名
A11: 10 | B11: AQ1009 | D11: 新北館 | E11: 新北家教會員 | G11: 0913521852 | I11: 儲值卡 | J11: 50040 | K11: 會員資料01.xls | L11: 家教等級
A12: 11 | B12: AQ108251 | C12: 陳吟榛、陳俐帆、陳姿穎 | D12: 新北課程 | E12: 一般會員 | G12: 0900000001 | I12: 儲值卡 | J12: 18000 | K12: 會員資料01.xls | L12: 課程群組、多人姓名
A13: 12 | B13: AQ109071 | C13: 陳名明、石家怡 | D13: 新北課程 | E13: 新北家教會員 | G13: 0939541957 | I13: 儲值卡 | J13: 7200 | K13: 會員資料01.xls | L13: 課程群組、家教等級、多人姓名
A14: 13 | B14: AQ109271 | C14: 許展睿 | D14: 新北課程 | E14: 新北家教會員 | G14: AQ0014 | I14: 儲值卡 | J14: 9000 | K14: 會員資料01.xls | L14: 課程群組、家教等級
A15: 14 | B15: AQ109288 | C15: 李紫晞、吳忻語、石家宜 | D15: 新北課程 | E15: 新北家教會員 | G15: 0937987666 | I15: 儲值卡 | J15: 7290 | K15: 會員資料01.xls | L15: 課程群組、家教等級、多人姓名
A16: 15 | B16: AQ109382 | C16: 陳宥均、陳宥任、陳宥齊 | D16: 新北課程 | E16: 新北家教會員 | G16: 0963099285 | I16: 儲值卡 | J16: 9000 | K16: 會員資料01.xls | L16: 課程群組、家教等級、多人姓名
A17: 16 | B17: AQ109427 | C17: 莊盛安、修樂菲 | D17: 新北館 | E17: 新北家教會員 | G17: 0978071701-1 | I17: 儲值卡 | J17: 6480 | K17: 會員資料01.xls | L17: 家教等級、多人姓名
A18: 17 | B18: AQ110010 | C18: 陳霖 | D18: 新北課程 | E18: 新北家教會員 | G18: 0953417659 | I18: 儲值卡 | J18: 31220 | K18: 會員資料01.xls | L18: 課程群組、家教等級
A19: 18 | B19: AQ110011 | C19: 黃子嫣 | D19: 新北課程 | E19: 新北家教會員 | G19: 0911111111 | I19: 儲值卡 | J19: 6600 | K19: 會員資料01.xls | L19: 課程群組、家教等級
A20: 19 | B20: AQ110069 | C20: 陳威霖、陳威丞 | D20: 新北課程 | E20: 新北家教會員 | G20: 0974512659 | I20: 儲值卡 | J20: 6120 | K20: 會員資料01.xls | L20: 課程群組、家教等級、多人姓名
A21: 20 | B21: AQ110086 | C21: 洪啟叡 | D21: 新北館 | E21: 新北家教會員 | G21: MQ09052970 | I21: 儲值卡 | J21: 6600 | K21: 會員資料01.xls | L21: 家教等級
A22: 21 | B22: AQ110093 | C22: 劉語晨 | D22: 新北課程 | E22: 新北家教會員 | G22: 0974596741 | I22: 儲值卡 | J22: 5400 | K22: 會員資料01.xls | L22: 課程群組、家教等級
A23: 22 | B23: AQ110103 | C23: 謝承勳 | D23: 新北課程 | E23: 新北家教會員 | G23: AQ0018 | I23: 儲值卡 | J23: 4800 | K23: 會員資料01.xls | L23: 課程群組、家教等級
... A33: 32 | B33: AQ111102 | C33: 周允文、周以暄 | D33: 新北館 | E33: 新北家教會員 | G33: 0972288989 | I33: 儲值卡 | J33: 43200 | K33: 會員資料01.xls | L33: 家教等級、多人姓名
A34: 33 | B34: AQ111111 | D34: 新北課程 | E34: 新北家教會員 | G34: AQ0013 | I34: 儲值卡 | J34: 19440 | K34: 會員資料01.xls | L34: 課程群組、家教等級
A35: 34 | B35: AQ111112 | D35: 新北課程 | E35: 新北家教會員 | G35: AQ0008 | I35: 儲值卡 | J35: 17280 | K35: 會員資料01.xls | L35: 課程群組、家教等級
A36: 35 | B36: AQ111118 | D36: 新北課程 | E36: 新北家教會員 | G36: AQ00000 | I36: 儲值卡 | J36: 9600 | K36: 會員資料01.xls | L36: 課程群組、家教等級
A37: 36 | B37: AQ111137 | C37: 游凡萱、李萬崴、周家呈 | D37: 新北館 | E37: 新北家教會員 | G37: AQ0011 | I37: 儲值卡 | J37: 13500 | K37: 會員資料01.xls | L37: 家教等級、多人姓名
A38: 37 | B38: AQ111140 | C38: 李昀桐、李翊菲 | D38: 新北課程 | E38: 新北家教會員 | G38: 111140111140 | I38: 儲值卡 | J38: 6120 | K38: 會員資料01.xls | L38: 課程群組、家教等級、多人姓名
A39: 38 | B39: AQ111142 | C39: 賴禹心賴楷承 | D39: 新北課程 | E39: 新北家教會員 | G39: 111142111142 | I39: 儲值卡 | J39: 12240 | K39: 會員資料01.xls | L39: 課程群組、家教等級、多人姓名
A40: 39 | B40: AQ111223 | C40: 鄧博誠 | D40: 新北課程 | E40: 新北家教會員 | G40: 0958623447 | I40: 儲值卡 | J40: 4800 | K40: 會員資料01.xls | L40: 課程群組、家教等級
A41: 40 | B41: AQ111235 | C41: 曾鈺婷、張豔秋 | D41: 新北課程 | E41: 新北家教會員 | G41: 0920087355 | I41: 儲值卡 | J41: 7200 | K41: 會員資料01.xls | L41: 課程群組、家教等級、多人姓名
A42: 41 | B42: AQ111247 | C42: 徐菁軒、徐鼎呈、陳香妘、潘柚岑 | D42: 新北館 | E42: 新北家教會員 | G42: 0917766323-1 | I42: 儲值卡 | J42: 8160 | K42: 會員資料01.xls | L42: 家教等級、多人姓名
A43: 42 | B43: AQ1112503 | C43: 呂乘澄、呂乘佳 | D43: 新北館 | E43: 一般會員 | G43: 0933221556 | I43: 儲值卡 | J43: 12960 | K43: 會員資料01.xls | L43: 多人姓名
A44: 43 | B44: AQ111260 | C44: 林愷杰、李赫雅 | D44: 新北課程 | E44: 新北家教會員 | G44: 0937544216 | I44: 儲值卡 | J44: 75600 | K44: 會員資料01.xls | L44: 課程群組、家教等級、多人姓名
A45: 44 | B45: AQ111263 | C45: 方心祈、方宥程 | D45: 新北課程 | E45: 新北家教會員 | G45: 0958741692 | I45: 儲值卡 | J45: 6120 | K45: 會員資料01.xls | L45: 課程群組、家教等級、多人姓名
A46: 45 | B46: AQ111275 | C46: 陳宥珊、連唯里、連唯亦 | D46: 新北課程 | E46: 新北家教會員 | G46: 111275111275 | I46: 儲值卡 | J46: 6885 | K46: 會員資料01.xls | L46: 課程群組、家教等級、多人姓名
A47: 46 | B47: AQ111282 | C47: 張智明 | D47: 新北課程 | E47: 新北家教會員 | G47: 0900000025 | I47: 儲值卡 | J47: 6600 | K47: 會員資料01.xls | L47: 課程群組、家教等級
A48: 47 | B48: AQ111294 | C48: 陳柏睿、陳柏宏、陳冠宏 | D48: 新北課程 | E48: 新北家教會員 | G48: 0911342957 | I48: 儲值卡 | J48: 6885 | K48: 會員資料01.xls | L48: 課程群組、家教等級、多人姓名
... A62: 61 | B62: AQ112049 | C62: 蘇少駒 | D62: 新北課程 | E62: 新北家教會員 | G62: 0958934001 | I62: 儲值卡 | J62: 19800 | K62: 會員資料01.xls | L62: 課程群組、家教等級
...
